Workbook
Name _Toc46209822: 目次!$A$5
Name _Toc77519344: 目次!#REF!
Name _Toc77519345: 目次!#REF!
Name _Toc77519346: 目次!#REF!

Sheet 表紙
K23: 第１．０版
K25: ＹＹＹＹ年Ｍ月Ｄ日
K32: [会社名]
K34: [部門名]

Sheet 変更履歴
A1: PJ名 | O1: 工程 | Y1: 作成
A2: システム名 | O2: 成果物名 | Q2: 業務コンポーネント責務配置 | Y2: 変更
A3: サブシステム名
N5: 変更履歴（ 1 / 1 ）
A7: No. | B7: 版数 | D7: 変更日 | G7: 区分 | J7: 変更箇所 | P7: 変更内容 | AE7: 担当者
J8: 頁 | L8: 項番

Sheet 目次
A1: PJ名 | E1: =IF(変更履歴!E1<>"",変更履歴!E1,"") | O1: 工程 | Q1: =IF(変更履歴!Q1<>"",変更履歴!Q1,"") | Y1: 作成 | AA1: =IF(変更履歴!AA1<>"",変更履歴!AA1,"") | AF1: =IF(変更履歴!AF1<>"",変更履歴!AF1,"")
A2: システム名 | E2: =IF(変更履歴!E2<>"",変更履歴!E2,"") | O2: 成果物名 | Q2: =IF(変更履歴!Q2<>"",変更履歴!Q2,"") -> 業務コンポーネント責務配置 | Y2: 変更 | AA2: =IF(変更履歴!AA2<>"",変更履歴!AA2,"") | AF2: =IF(変更履歴!AF2<>"",変更履歴!AF2,"")
A3: サブシステム名 | E3: =IF(変更履歴!E3<>"",変更履歴!E3,"")
Q5: 目次（１／１）
A7: 1. はじめに
B8: 1.1. 本書の位置づけ
A10: 2. ステレオタイプ
B11: 2.1. 業務コンポーネントのステレオタイプと、その関連図
B12: 2.2. 業務コンポーネントの基本的な処理シーケンス
A14: 3. ソースコードの自動生成
B15: 3.1. 自動生成するソースコード
B16: 3.2. 業務ベースフォームの自動生成
B17: 3.3. エンティティの自動生成
B18: 3.4. 排他制御主キークラスの自動生成
A20: 3. 単体テスト
B21: 3.1. 単体テスト範囲・分類
B22: 3.2. 単体テスト方針
A24: 4. 画面オンライン実行制御基盤を使用する場合の責務配置パターン
B25: 4.1. 通常の画面遷移
B26: 4.2. ファイルアップロード
B27: 4.3. ファイルダウンロード
A29: 5. バッチ実行制御基盤を使用する場合の責務配置パターン
B30: 5.1. データベース入力バッチおよびファイル入力バッチ
A32: 6. メッセージング実行制御基盤を使用する場合の責務配置パターン
B33: 6.1. 同期応答メッセージ受信処理
B34: 6.2. 応答不要メッセージ受信処理
B35: 6.3. 応答不要メッセージ送信処理

Sheet はじめに
A1: PJ名 | E1: =IF(変更履歴!E1<>"",変更履歴!E1,"") | O1: 工程 | Q1: =IF(変更履歴!Q1<>"",変更履歴!Q1,"") | Y1: 作成 | AA1: =IF(変更履歴!AA1<>"",変更履歴!AA1,"") | AF1: =IF(変更履歴!AF1<>"",変更履歴!AF1,"")
A2: システム名 | E2: =IF(変更履歴!E2<>"",変更履歴!E2,"") | O2: 成果物名 | Q2: =IF(変更履歴!Q2<>"",変更履歴!Q2,"") -> 業務コンポーネント責務配置 | Y2: 変更 | AA2: =IF(変更履歴!AA2<>"",変更履歴!AA2,"") | AF2: =IF(変更履歴!AF2<>"",変更履歴!AF2,"")
A3: サブシステム名 | E3: =IF(変更履歴!E3<>"",変更履歴!E3,"")
A5: 1. はじめに
B7: 1.1 本書の位置づけ
C9: 本書では、【方式設計書(アプリケーション処理方式)】にて定義されている、業務コンポーネントを構成する各要素（以下、ステレオタイプと呼ぶ）の責務について解説する。
C11: また、本プロジェクトでの業務コンポーネントの単体テスト対象とする範囲についても記載する。

Sheet ステレオタイプ
A1: PJ名 | E1: =IF(変更履歴!E1<>"",変更履歴!E1,"") | T1: 工程 | V1: =IF(変更履歴!Q1<>"",変更履歴!Q1,"") | AM1: 作成 | AO1: =IF(変更履歴!AA1<>"",変更履歴!AA1,"") | AU1: =IF(変更履歴!AF1<>"",変更履歴!AF1,"")
A2: システム名 | E2: =IF(変更履歴!E2<>"",変更履歴!E2,"") | T2: 成果物名 | V2: =IF(変更履歴!Q2<>"",変更履歴!Q2,"") -> 業務コンポーネント責務配置 | AM2: 変更 | AO2: =IF(変更履歴!AA2<>"",変更履歴!AA2,"") | AU2: =IF(変更履歴!AF2<>"",変更履歴!AF2,"")
A3: サブシステム名 | E3: =IF(変更履歴!E3<>"",変更履歴!E3,"")
A5: 2. ステレオタイプ
B7: 2.1. 業務コンポーネントのステレオタイプと、その関連図
C9: 業務コンポーネント（アプリケーションプログラマが作成するコンポーネント）のステレオタイプと、その関連図は以下のようになる。
AD10: ① 業務アクション
AE11: 実行制御基盤に依存した処理と取引固有の業務ロジックを実装するクラス。主に、以下の内容を実装する。
AE12: ・ 入力データのフォームへの変換
AF13: 業務フォームの精査ロジックを使用して入力データを精査し、業務フォームを生成する。
AE14: ・ 排他制御
AF15: 楽観ロック、悲観ロック用のバージョン番号の取得、確認、更新
AE16: ・ 業務ロジックの実行
AF17: DB相関精査、データベースアクセス、業務共通コンポーネントの呼び出しなど
AE18: ・ 処理結果の生成、返却
AF19: リクエストスコープへの処理結果の格納、応答電文の作成、バッチ終了コードの設定など
AD21: ② 業務共通コンポーネント
AE22: 実行制御基盤に依存せず、複数の業務アクションから呼び出される共通の業務ロジックを実装する。
AE23: ・業務ロジックの実行
AF24: データベースアクセス、業務共通コンポーネントの呼び出しなど
AE25: 業務共通コンポーネントは、その共通化の範囲（共通コンポーネントが使用されるスコープ）に応じて、
AE26: 以下の3つに分類される。
AF27: ・システム内共通コンポーネント：システム全体で共通の業務ロジック
AF28: ・サブシステム内共通コンポーネント：サブシステム内のみで共通の業務ロジック
AF29: ・機能内共通コンポーネント：機能内のみで共通の業務ロジック
AD31: ③ 業務ベースフォーム
AE32: 入力データ定義を元に自動生成するオブジェクトで、入力データの単項目精査を実装する。
AE33: ※本クラスは入力データ定義を元に自動生成されるため、生成されたソースコードに対する修正は禁止する。
AE34: 自動生成されたベースフォームへの機能追加は、後述の「④業務フォーム」に実装する。
AD36: ④ 業務フォーム
AE37: 入力データに対する精査処理を実装する。
AE38: ・単項目精査
AF39: 入力データ定義に記載されておらず、自動生成ではベースフォームに定義されない
AF40: 入力データに対する単項目精査を実装する。
AG41: ※画面オンラインにおける、hiddenでの引継ぎ項目など
AE42: ・項目間精査
AF43: 複数の項目を使用した精査を実装する。
AD45: ⑤ エンティティ
AE46: テーブルと1対1に紐づき、テーブルの列に対応するプロパティをもつオブジェクト
AE47: ※本クラスは、設計書を元に自動生成するため、生成されたソースコードへの修正は禁止する。
...

Sheet ソースコードの自動生成
A1: PJ名 | E1: =IF(変更履歴!E1<>"",変更履歴!E1,"") | T1: 工程 | V1: =IF(変更履歴!Q1<>"",変更履歴!Q1,"") | AM1: 作成 | AO1: =IF(変更履歴!AA1<>"",変更履歴!AA1,"") | AU1: =IF(変更履歴!AF1<>"",変更履歴!AF1,"")
A2: システム名 | E2: =IF(変更履歴!E2<>"",変更履歴!E2,"") | T2: 成果物名 | V2: =IF(変更履歴!Q2<>"",変更履歴!Q2,"") -> 業務コンポーネント責務配置 | AM2: 変更 | AO2: =IF(変更履歴!AA2<>"",変更履歴!AA2,"") | AU2: =IF(変更履歴!AF2<>"",変更履歴!AF2,"")
A3: サブシステム名 | E3: =IF(変更履歴!E3<>"",変更履歴!E3,"")
A5: 3. ソースコードの自動生成
B7: 3.1. 自動生成するソースコード
C9: 「2.1 業務コンポーネントのステレオタイプ図」に記載されているステレオタイプのうち、以下のステレオタイプについては、ソースコードを自動生成する。
D11: ・業務ベースフォーム
D12: ・エンティティ
C14: また、ステレオタイプとしては記載していないが、以下のクラスも自動生成する。
D16: ・排他制御主キークラス（排他制御を行う際に排他制御対象を特定するために使用するクラス）
B19: 3.2. 業務ベースフォームの自動生成
C21: 業務ベースフォームは、画面入力項目に対応するフォームを生成する場合と、ファイルや電文などの外部インターフェース設計に対応するフォームを生成する場合で、生成方法が異なる。
C23: 3.2.1 画面入力項目に対応する業務ベースフォームの自動生成
D25: UI開発基盤のフォームクラス生成機能を使用して、JSPファイルからフォームクラスのソースコードを自動生成する。
C50: 3.2.2 外部インターフェース設計に対応するフォームの自動生成
D52: Form自動生成ツールを使用して、外部インターフェース設計書・ドメイン定義書から、フォームクラスのソースコードを自動生成する。
B69: 3.3. エンティティの自動生成
C71: Form自動生成ツールを使用して、テーブル定義書・ドメイン定義書から、エンティティクラスのソースコードを自動生成する。
B88: 3.4. 排他制御主キークラスの自動生成
C90: 排他制御主キークラス自動生成ツールを使用して、テーブル定義書から、排他制御テーブル主キークラスのソースコードを生成する。

Sheet 単体テスト
A1: PJ名 | E1: =IF(変更履歴!E1<>"",変更履歴!E1,"") | T1: 工程 | V1: =IF(変更履歴!Q1<>"",変更履歴!Q1,"") | AM1: 作成 | AO1: =IF(変更履歴!AA1<>"",変更履歴!AA1,"") | AU1: =IF(変更履歴!AF1<>"",変更履歴!AF1,"")
A2: システム名 | E2: =IF(変更履歴!E2<>"",変更履歴!E2,"") | T2: 成果物名 | V2: =IF(変更履歴!Q2<>"",変更履歴!Q2,"") -> 業務コンポーネント責務配置 | AM2: 変更 | AO2: =IF(変更履歴!AA2<>"",変更履歴!AA2,"") | AU2: =IF(変更履歴!AF2<>"",変更履歴!AF2,"")
A3: サブシステム名 | E3: =IF(変更履歴!E3<>"",変更履歴!E3,"")
A5: 4. 単体テスト
B7: 4.1. 単体テスト範囲・分類
C9: 本プロジェクトでは、取引(※1)もしくは共通コンポーネントの単体での品質を保証するために実施するテストを単体テストと呼称する。
C10: ※1 取引とは、一連のリクエストから成る業務的な意味を持つ最小単位を指し、1つのシステム機能設計書に対応する。
C12: 単体テストは、テスト対象とする範囲に応じて以下の3つのテストに分類する。
C14: テスト名 | I14: 説明
C15: クラス単体テスト | I15: 各ステレオタイプの実行制御基盤に依存しない処理について、クラス単体で正しく実行されることを確認する。
C17: リクエスト単体テスト | I17: 実行制御基盤と各ステレオタイプを結合し、リクエスト単位で正しく実行されることを確認する。
C19: 取引単体テスト | I19: リクエストを結合し、取引の業務処理が正しく実行されることを確認する。
I20: また、打鍵あるいは目視での確認が必要なテスト観点に関して、正しく実行されていることを確認する。
C23: Nablarch Testing Framework を用いた単体テストの実施方法については、Nablarchの【プログラミング・単体テストガイド】を参照すること。
B25: 4.2. 単体テスト方針
C27: 単体テストを全体で最適化し、初回作成時の工数や仕様変更時、回帰テスト時の修正工数を削減するために、以下の方針に従って単体テストを実施するものとする。
D29: 1）目視確認が適している、かつ回帰テストの自動化効果が薄いものは取引単体テストを実施する。
D30: 目視確認が適しているテストのうち、リクエスト単体テストで実施することで打鍵作業を省力化できるものについては、リクエスト単体テストを実行して生成される成果物を確認する。
D31: 例えば、画面オンライン処理での全ての精査エラーメッセージの表示確認などは、リクエスト単体テストで生成されるHTMLを確認し、取引単体テストでは実施しない。
D32: 2）自動テストが適しているものはクラス単体テストもしくはリクエスト単体テストを実施する。
D33: テストの実施内容の粒度とテスト対象の範囲が一致するように実施し、クラス単体テストとリクエスト単体テスト間でのテスト実施内容の重複は排除する。
D34: 例えば、パターン網羅などのテストはクラス単体テストで実施し、リクエスト単体テストでは実施しない。
D35: 3）自動生成されたソースコードを修正しない場合は、当該クラス用の自動テストを作成しない。
C37: 以下に、基本的なステレオタイプごとの責務と、テスト実施のマトリクスを示す。
C38: 典型的な処理ごとの、確認観点と実施テストのマトリクスの詳細は、次章以降に記載している。
C40: ステレオタイプ | I40: 責務 | T40: クラス単体テスト | X40: リクエスト単体テスト | AC40: 取引単体テスト
C41: 業務アクション | I41: 排他制御 | X41: △ ※1 | AC41: ○ ※1
I42: 入力データの業務フォームへの変換 | X42: ○
I43: 業務ロジックの実行 | T43: ○ ※2 | X43: △ ※2
I44: 処理結果の生成、返却 | X44: △ ※1 | AC44: ○ ※1
C45: 業務共通コンポーネント | I45: 業務ロジックの実行 | T45: ○
C46: 業務フォーム | I46: 入力データ定義に対応しない項目の単項目精査 | T46: ○
I47: 項目間精査 | T47: ○
C48: 業務ベースフォーム | I48: 入力データ定義に対応する項目の単項目精査 | T48: 自動生成のため、テスト対象外
C49: エンティティ | I49: データベースに保存する値の格納 | T49: 自動生成のため、テスト対象外
C50: ※1 画面オンライン実行制御基盤では、取引単体テストでの確認が必須であり、取引単体テストで確認される内容については、リクエスト単体テストでは実施しない。
C51: それ以外の実行制御基盤の場合は、リクエスト単体テストのみで実施する。
C52: ※2 メッセージ同期応答送信処理など、Nablarchの制約によりクラス単体テストで実施できないテストのみリクエスト単体テストで実施する。

Sheet 責務配置パターン（画面）
A1: PJ名 | E1: =IF(変更履歴!E1<>"",変更履歴!E1,"") | T1: 工程 | V1: =IF(変更履歴!Q1<>"",変更履歴!Q1,"") | AM1: 作成 | AO1: =IF(変更履歴!AA1<>"",変更履歴!AA1,"") | AU1: =IF(変更履歴!AF1<>"",変更履歴!AF1,"")
A2: システム名 | E2: =IF(変更履歴!E2<>"",変更履歴!E2,"") | T2: 成果物名 | V2: =IF(変更履歴!Q2<>"",変更履歴!Q2,"") -> 業務コンポーネント責務配置 | AM2: 変更 | AO2: =IF(変更履歴!AA2<>"",変更履歴!AA2,"") | AU2: =IF(変更履歴!AF2<>"",変更履歴!AF2,"")
A3: サブシステム名 | E3: =IF(変更履歴!E3<>"",変更履歴!E3,"")
A5: 5. 画面オンライン実行制御基盤を使用する場合の責務配置パターン
B7: 本章では、画面オンライン実行制御基盤を使用する各処理パターンごとにステレオタイプの配置パターン及び単体テストで対象とするテスト範囲について説明する。
B9: 5.1. 通常の画面遷移
C11: 5.1.1. 責務配置とテスト範囲
AO33: ※自動生成・共通機能またはNablarch提供クラス
C43: 各ステレオタイプに対応する設計書、責務および、各単体テストでの確認観点の一覧は、以下のようになる。
C44: 設計書 | H44: ステレオタイプ | N44: 責務 | Z44: クラス単体テストでの確認観点 | AH44: リクエスト単体テストでの確認観点 | AP44: 取引単体テストでの確認観点
C45: システム機能設計書 ドメイン定義書 | H45: 遷移元画面 | N45: 取引の実行 | Q45: パラメータ送信 | AP45: 取引の実行 | AS45: ■引継ぎ項目
C46: 画面遷移図 | H46: 遷移先画面 | Q46: 処理結果の画面表示 | AH46: ■画面レイアウト、画面項目定義 | AS46: ■JavaScriptの動作確認
C47: システム機能設計書 画面遷移図 | H47: 業務アクション | Q47: 入力データのフォームへの変換 | AH47: ■業務フォームの精査メソッドの呼出し
Q48: 排他制御 | AS48: ■排他制御の確認 ・楽観ロック用バージョン番号の取得、確認、更新
Q49: 業務ロジックの実行 | Z49: ■業務ロジックの妥当性確認 ・計算処理、導出処理 ・DB相関精査 ・データベースアクセス仕様 ・送信メール仕様 ■業務共通コンポーネントのメソッド呼び出し確認 | AH49: ■業務ロジックの妥当性確認 ・送信電文仕様 ・受信電文仕様
Q50: 処理結果の生成、返却 | AH50: ■処理結果の生成、返却 ※1 ・画面表示データをリクエストスコープに格納 ・フォワード先の設定 | AS50: ■処理結果の生成、返却 ・画面表示データをリクエストスコープに格納 ・フォワード先の設定
Q51: 2重サブミット防止 | AH51: ■2重サブミット防止（サーバサイド） | AS51: ■2重サブミット防止（クライアントサイド）
C52: システム機能設計書 | H52: 業務フォーム | Q52: 引継ぎ項目の単項目精査 | Z52: ■精査処理の確認
C53: ドメイン定義書 | Q53: 項目間精査
H54: 業務ベースフォーム | Q54: 画面入力項目の単項目精査 | Z54: （自動生成のためテスト対象外） | AH54: （自動生成のためテスト対象外） | AS54: （自動生成のためテスト対象外）
C55: テーブル定義書 | H55: エンティティ | Q55: データベースに保存する値の格納 | Z55: （自動生成のためテスト対象外） | AH55: （自動生成のためテスト対象外） | AS55: （自動生成のためテスト対象外）
C57: コンポーネント設計書 | H57: 業務共通コンポーネント | N57: 共通ロジックの実行 | Z57: ■共通ロジックの妥当性確認 ・計算処理、導出処理 ・DB相関精査 ・データベースアクセス仕様 ・送信メール仕様 ■業務共通コンポーネントのメソッド呼び出し確認 | AH57: ■共通ロジックの妥当性確認 ・送信電文仕様 ・受信電文仕様
C58: ※1 取引単体テストケースで網羅できない場合のみ、リクエスト単体テストで実施する。
C61: 5.1.2. 更新処理の処理シーケンス
D63: 画面オンライン実行制御基盤で使用される業務コンポーネントの基本的な処理シーケンスを、更新処理を例として記載する。
D64: 照会処理・登録処理・削除処理などは、処理シーケンスとしては更新時の各処理とは排他制御の実施有無のみ異なり、その他の必要な処理の実施順序は同様である。
D66: ① 初期表示処理
D99: ② 確認処理
D135: ③ 確定処理
B170: 5.2. ファイルアップロード
AO193: ※自動生成・共通機能またはNablarch提供クラス
C210: 各ステレオタイプに対応する設計書、責務および、各単体テストでの確認観点の一覧は、以下のようになる。なお、「3.1. 通常の画面遷移のみのパターン」と異なる箇所のみ記載している。
C211: 設計書 | H211: ステレオタイプ | N211: 責務 | Z211: クラス単体テスト | AH211: リクエスト単体テスト | AP211: 取引単体テスト
C212: システム機能設計書 | H212: 業務アクション | N212: 取引の実行 | Q212: 業務ロジックの実行 | Z212: ■業務ロジックの妥当性確認 ・計算処理、導出処理 ・DB相関精査 ・データベースアクセス仕様 ・送信メール仕様 ■業務共通コンポーネントのメソッド呼び出し確認 | AH212: ■業務ロジックの妥当性確認 ・アップロードファイル取込処理 ・送信電文仕様 ・受信電文仕様 | AP212: 取引の実行
C213: 外部インターフェース設計書 | H213: ファイルフォーム | Q213: 項目間精査 | Z213: ■精査処理の妥当性確認
C214: ドメイン定義書 | H214: ファイルベースフォーム | Q214: 単項目精査 | Z214: （自動生成のためテスト対象外） | AH214: （自動生成のためテスト対象外） | AS214: （自動生成のためテスト対象外）
B217: 5.3. ファイルダウンロード
AO240: ※自動生成・共通機能またはNablarch提供クラス
C249: 各ステレオタイプに対応する設計書、責務および、各単体テストでの確認観点の一覧は、以下のようになる。なお、「3.1. 通常の画面遷移のみのパターン」と異なる箇所のみ記載している。
C250: 設計書 | H250: ステレオタイプ | N250: 責務 | Z250: クラス単体テスト | AH250: リクエスト単体テスト | AP250: 取引単体テスト
...

Sheet 責務配置パターン（バッチ）
A1: PJ名 | E1: =IF(変更履歴!E1<>"",変更履歴!E1,"") | T1: 工程 | V1: =IF(変更履歴!Q1<>"",変更履歴!Q1,"") | AM1: 作成 | AO1: =IF(変更履歴!AA1<>"",変更履歴!AA1,"") | AU1: =IF(変更履歴!AF1<>"",変更履歴!AF1,"")
A2: システム名 | E2: =IF(変更履歴!E2<>"",変更履歴!E2,"") | T2: 成果物名 | V2: =IF(変更履歴!Q2<>"",変更履歴!Q2,"") -> 業務コンポーネント責務配置 | AM2: 変更 | AO2: =IF(変更履歴!AA2<>"",変更履歴!AA2,"") | AU2: =IF(変更履歴!AF2<>"",変更履歴!AF2,"")
A3: サブシステム名 | E3: =IF(変更履歴!E3<>"",変更履歴!E3,"")
A5: 6. バッチ実行制御基盤を使用する場合の責務配置パターン
B7: 本章では、バッチ実行制御基盤を使用する場合のステレオタイプの配置パターン及び単体テストで対象とするテスト範囲について説明する。
B9: 6.1. データベース入力バッチおよびファイル入力バッチ
C11: 6.1.1. 責務配置とテスト範囲
AO33: ※自動生成・共通機能またはNablarch提供クラス
C48: 各ステレオタイプに対応する設計書、責務および、各単体テストでの確認観点の一覧は、以下のようになる。
C49: 設計書 | H49: ステレオタイプ | N49: 責務 | Z49: クラス単体テストでの確認観点 | AH49: リクエスト単体テストでの確認観点 | AS49: 取引単体テストでの確認観点
C50: システム機能設計書 | H50: 業務アクション | N50: バッチ処理の実行 | Q50: 入力データのフォームへの変換 ※1 | AH50: バッチ処理の実行 | AK50: ■ファイルフォームの精査メソッドの呼出し確認 ※1 | AS50: 後続のバッチ処理との結合
Q51: 排他制御 | AK51: ■排他制御の確認
Q52: 業務ロジックの実行 | Z52: ■業務ロジックの妥当性確認 ・計算処理、導出処理 ・DB相関精査 ・データベースアクセス仕様 ・送信メール仕様 ・出力ファイル仕様 ■業務共通コンポーネントのメソッド呼び出し確認 | AK52: ■入力データパターンごとの処理の妥当性確認 ■業務ロジックの妥当性確認 ・送信電文仕様 ・受信電文仕様 ・ログ出力仕様
Q53: 処理結果の生成、返却 | AK53: ■処理結果の確認
C54: 外部インターフェース設計書 | H54: ファイルフォーム | Q54: 項目間精査 | Z54: ■精査処理の妥当性確認
C55: ドメイン定義書 | H55: ファイルベースフォーム | Q55: ファイルレコードの項目に対する単項目精査 | Z55: （自動生成のためテスト対象外） | AK55: （自動生成のためテスト対象外）
C56: テーブル定義書 | H56: エンティティ | Q56: データベースに保存する値の格納 | Z56: （自動生成のためテスト対象外） | AK56: （自動生成のためテスト対象外）
C58: コンポーネント設計書 | H58: 業務共通コンポーネント | N58: 共通ロジックの実行 | Z58: ■業務ロジックの妥当性確認 ・計算処理、導出処理 ・DB相関精査 ・データベースアクセス仕様 ・送信メール仕様 ■業務共通コンポーネントのメソッド呼び出し確認 | AH58: ■共通ロジックの妥当性確認 ・送信電文仕様 ・受信電文仕様
C59: ※1 入力データをファイルから読み込む場合のみ
C62: 6.1.2. データベース入力バッチの処理シーケンス
C112: 6.1.3. ファイル入力バッチの処理シーケンス

Sheet 責務配置パターン（メッセージング）
A1: PJ名 | E1: =IF(変更履歴!E1<>"",変更履歴!E1,"") | T1: 工程 | V1: =IF(変更履歴!Q1<>"",変更履歴!Q1,"") | AM1: 作成 | AO1: =IF(変更履歴!AA1<>"",変更履歴!AA1,"") | AU1: =IF(変更履歴!AF1<>"",変更履歴!AF1,"")
A2: システム名 | E2: =IF(変更履歴!E2<>"",変更履歴!E2,"") | T2: 成果物名 | V2: =IF(変更履歴!Q2<>"",変更履歴!Q2,"") -> 業務コンポーネント責務配置 | AM2: 変更 | AO2: =IF(変更履歴!AA2<>"",変更履歴!AA2,"") | AU2: =IF(変更履歴!AF2<>"",変更履歴!AF2,"")
A3: サブシステム名 | E3: =IF(変更履歴!E3<>"",変更履歴!E3,"")
A5: 7. メッセージング実行制御基盤を使用する場合の責務配置パターン
B7: 本章では、メッセージング実行制御基盤を使用する場合のステレオタイプの配置パターン及び単体テストで対象とするテスト範囲について説明する。
B9: 7.1. 同期応答メッセージ受信処理
C11: 7.1.1. 責務配置とテスト範囲
AO33: ※自動生成・共通機能またはNablarch提供クラス
C45: 各ステレオタイプに対応する設計書、責務および、各単体テストでの確認観点の一覧は、以下のようになる。
C46: 設計書 | H46: ステレオタイプ | N46: 責務 | Z46: クラス単体テストでの確認観点 | AH46: リクエスト単体テストでの確認観点 | AS46: 取引単体テストでの確認観点
C47: システム機能設計書 | H47: 業務アクション | N47: 同期応答処理の実行 | Q47: 入力データのフォームへの変換 | AH47: 同期応答処理の実行 | AK47: ■電文フォームの精査メソッドの呼出し確認 | AS47: 後続のバッチ処理との結合
Q48: 排他制御 | AK48: ■排他制御の確認
Q49: 業務ロジックの実行 | Z49: ■業務ロジックの妥当性確認 ・計算処理、導出処理 ・DB相関精査 ・データベースアクセス仕様 ・送信メール仕様 ・出力ファイル仕様 ■業務共通コンポーネントのメソッド呼び出し確認 | AK49: ■入力データパターンごとの処理の妥当性確認 ■業務ロジックの妥当性確認 ・送信電文仕様 ・受信電文仕様
Q50: 処理結果の生成、返却 | AK50: ■処理結果の確認
C51: 外部インターフェース設計書 | H51: 電文フォーム | Q51: 項目間精査 | Z51: ■精査処理の妥当性確認
C52: ドメイン定義書 | H52: 電文ベースフォーム | Q52: 単項目精査 | Z52: （自動生成のためテスト対象外） | AK52: （自動生成のためテスト対象外）
C53: テーブル定義書 | H53: エンティティ | Q53: データベースに保存する値の格納 | Z53: （自動生成のためテスト対象外） | AK53: （自動生成のためテスト対象外）
C55: コンポーネント設計書 | H55: 業務共通コンポーネント | N55: 共通ロジックの実行 | Z55: ■業務ロジックの妥当性確認 ・計算処理、導出処理 ・DB相関精査 ・データベースアクセス仕様 ・送信メール仕様 ■業務共通コンポーネントのメソッド呼び出し確認 | AH55: ■共通ロジックの妥当性確認 ・送信電文仕様 ・受信電文仕様
C58: 7.1.2. 同期応答メッセージ受信処理の処理シーケンス
B96: 7.2. 応答不要メッセージ受信処理
C98: 7.2.1. 責務配置とテスト範囲
AP120: ※自動生成・共通機能またはNablarch提供クラス
D121: 上記の責務配置図からも分かるとおり、Nablarchの提供する「応答不要電文受信処理用アクションハンドラ」を使用する応答不要メッセージ受信処理については、
D122: 各ステレオタイプが業務処理などの責務を持たないためクラス単体テストの実施は不要とする。
D124: 「電文登録用SQL」については、リクエスト単体テストで「応答不要電文受信処理用アクションハンドラ」と結合してテストを実施する。
C126: 7.2.2. 応答不要メッセージ受信処理の処理シーケンス
B146: 7.3. 応答不要メッセージ送信処理
C148: 7.3.1. 責務配置とテスト範囲
AP171: ※自動生成・共通機能またはNablarch提供クラス
D173: 上記の責務配置図からも分かるとおり、Nablarchの提供する「応答不要電文送信処理用アクションハンドラ」を使用する応答不要メッセージ受信処理については、
D174: 各ステレオタイプが業務処理などの責務を持たないためクラス単体テストの実施は不要とする。
D176: 「送信電文データ取得・ステータス更新用SQL」については、リクエスト単体テストで「応答不要電文送信処理用アクションハンドラ」と結合してテストを実施する。
C178: 7.3.2. 応答不要メッセージ送信処理の処理シーケンス
